<?xml version='1.0'?>

<robot name="st" xmlns:xacro="http://www.ros.org/wiki/xacro">

  <xacro:include filename="$(find mybot)/urdf/st.gazebo"/>
  <xacro:include filename="$(find mybot)/urdf/imu_plugin.xacro"/>
  <link name='base_link'>
    <pose>0 0 0.1 0 0 0</pose>

    <inertial>
      <mass value="5.0"/>
      <origin xyz="0.0 0 0.1" rpy=" 0 0 0"/>
      <inertia
          ixx="0.1" ixy="0" ixz="0"
          iyy="0.1" iyz="0"
          izz="0.1"
      />
    </inertial>

    <collision name='collision'>
      <geometry>
        <box size=".4 .2 .1"/>
      </geometry>
    </collision>

    <visual name='chassis_visual'>
      <origin xyz="0 0 0" rpy=" 0 0 0"/>
      <geometry>
        <box size=".4 .2 .1"/>
      </geometry>
        <material name="grey">
    <color rgba="0.5 0.5 0.5 1.0"/>
  </material>
    </visual>

    <visual name='chassis_visual_top'>
      <origin xyz="-0.1 0 0.05" rpy=" 0 0 0"/>
      <geometry>
        <box size=".1 .2 .08"/>
      </geometry>
        <material name="green">
    <color rgba="0.0 0.8 0.0 1.0"/>
    </material>
    </visual>

    <collision name='caster_collision'>
      <origin xyz="-0.15 0 -0.04" rpy=" 0 1.5708 -1.5708"/>
      <geometry>
        <cylinder radius="0.05" length="0.05"/>
      </geometry>
    </collision>

    <visual name='caster_visual'>
      <origin xyz="-0.15 0 -0.04" rpy=" 0 1.5708 -1.5708"/>
      <geometry>
        <cylinder radius="0.05" length="0.05"/>
      </geometry>
      <material name="black">
    <color rgba="0.0 0.0 0.0 1.0"/>
  </material>
    </visual>

    <collision name='caster_front_collision'>
      <origin xyz="0.15 0 -0.04" rpy=" 0 0 0"/>
      <geometry>
        <sphere radius="0.05"/>
      </geometry>
    </collision>

    <visual name='caster_front_visual'>
      <origin xyz="0.15 0 -0.04" rpy=" 0 0 0"/>
      <geometry>
        <sphere radius="0.05"/>
      </geometry>
        <material name="black">
    <color rgba="0.0 0.0 0.0 1.0"/>
  </material>
  </visual>
  </link>


  <link name="left_wheel">
    <!--origin xyz="0.1 0.13 0.1" rpy="0 1.5707 1.5707"/-->
    <collision name="collision">
      <origin xyz="0 0 0" rpy="0 1.5707 1.5707"/>
      <geometry>
        <cylinder radius="0.1" length="0.05"/>
      </geometry>
    </collision>
    <visual name="left_wheel_visual">
      <origin xyz="0 0 0" rpy="0 1.5707 1.5707"/>
      <geometry>
        <cylinder radius="0.1" length="0.05"/>
      </geometry>
    <material name="black">
        <color rgba="0.0 0.0 0.0 1.0"/>
    </material>
    </visual>
    <inertial>
      <origin xyz="0 0 0" rpy="0 1.5707 1.5707"/>
      <mass value="5"/>
      <inertia
        ixx=".1" ixy="0.0" ixz="0.0"
        iyy=".1" iyz="0.0"
        izz=".1"/>
    </inertial>
  </link>

  <link name="right_wheel">
    <!--origin xyz="0.1 -0.13 0.1" rpy="0 1.5707 1.5707"/-->
    <collision name="collision">
      <origin xyz="0 0 0" rpy="0 1.5707 1.5707"/>
      <geometry>
        <cylinder radius="0.1" length="0.05"/>
      </geometry>
    </collision>
    <visual name="right_wheel_visual">
      <origin xyz="0 0 0" rpy="0 1.5707 1.5707"/>
      <geometry>
        <cylinder radius="0.1" length="0.05"/>
      </geometry>
        <material name="black">
            <color rgba="0.0 0.0 0.0 1.0"/>
        </material>
    </visual>
    <inertial>
      <origin xyz="0 0 0" rpy="0 1.5707 1.5707"/>
      <mass value="5"/>
      <inertia
        ixx=".1" ixy="0.0" ixz="0.0"
        iyy=".1" iyz="0.0"
        izz=".1"/>
    </inertial>
  </link>


  <joint type="continuous" name="left_wheel_hinge">
    <origin xyz="-0.07 0.15 0" rpy="0 0 0"/>
    <!--origin xyz="0.1 0.13 0" rpy="0 1.5707 1.5707"/-->
    <child link="left_wheel"/>
    <parent link="base_link"/>
    <axis xyz="0 1 0" rpy="0 0 0"/>
    <!-- <limit effort="10000" velocity="1000"/> -->
    <joint_properties damping="0.0" friction="0.0"/>
  </joint>

  <joint type="continuous" name="right_wheel_hinge">
    <origin xyz="-0.07 -0.15 0" rpy="0 0 0"/>
    <!--origin xyz="0.1 -0.13 0" rpy="0 1.5707 1.5707"/-->
    <child link="right_wheel"/>
    <parent link="base_link"/>
    <axis xyz="0 1 0" rpy="0 0 0"/>
    <!-- <limit effort="10000" velocity="1000"/> -->
    <joint_properties damping="0.0" friction="0.0"/>
  </joint>

  <!-- Hokuyo Laser -->
  <link name="hokuyo_link">
    <collision>
      <origin xyz="0 0 0" rpy="0 0 0"/>
      <geometry>
        <box size="0.1 0.1 0.1"/>
      </geometry>
    </collision>

    <visual>
      <origin xyz="0 0 0" rpy="0 0 0"/>
      <geometry>
        <mesh filename="package://mybot/meshes/hokuyo.dae"/>
      </geometry>
    </visual>

    <inertial>
      <mass value="1e-5" />
      <origin xyz="0 0 0" rpy="0 0 0"/>
      <inertia ixx="1e-6" ixy="0" ixz="0" iyy="1e-6" iyz="0" izz="1e-6" />
    </inertial>
  </link>

  <joint name="hokuyo_joint" type="fixed">
    <axis xyz="0 1 0" />
    <origin xyz="0.15 0 0.08" rpy="0 0 0"/>
    <parent link="base_link"/>
    <child link="hokuyo_link"/>
  </joint> 

 <!-- imu Link -->
  <link name="imu_sensor">
    <visual>
      <origin xyz="0.04 0 0.05" rpy="0 0 0"/>
      <geometry>
        <box size="0.07 0.07 0.03"/>
      </geometry>
      <material name="orange"/>
    </visual>

    <inertial>
      <origin xyz="0 0 1" rpy="0 0 0"/>
      <mass value="1"/>
      <inertia
        ixx="1.0" ixy="0.0" ixz="0.0"
        iyy="1.0" iyz="0.0"
        izz="1.0"/>
    </inertial>
  </link>
  <joint name="sensor_joint" type="fixed">
    <parent link="base_link"/>
    <child link="imu_sensor"/>
  </joint>

<!-- gps Link -->
  <link name="gps_link">

    <visual name='gps_r'>
    <origin xyz="0.03 -0.07 0.06" rpy="0 3.14 1.5708"/>
      <geometry>
        <cylinder radius="0.01" length="0.05"/>
      </geometry>
      <material name="blue">
        <color rgba="${50/255} ${10/255} ${255/255} 1.0"/>
      </material>
    </visual>

    <visual name = "gps_l">
      <origin xyz="0.03 0.07 0.06" rpy="0 3.14 1.5708"/>
      <geometry>
        <cylinder radius="0.01" length="0.05"/>
      </geometry>
      <material name="blue">
        <color rgba="${50/255} ${10/255} ${255/255} 1.0"/>
      </material>
    </visual>

    <inertial>
      <origin xyz="0 0 1" rpy="0 0 0"/>
      <mass value="1"/>
      <inertia
        ixx="1.0" ixy="0.0" ixz="0.0"
        iyy="1.0" iyz="0.0"
        izz="1.0"/>
    </inertial>
  </link>

  <joint name="sensor_gps_joint" type="fixed">
    <parent link="base_link"/>
    <child link="gps_link"/>
  </joint>


  <material name="orange">
    <color rgba="${255/255} ${108/255} ${10/255} 1.0"/>
  </material>


</robot>

