<?xml version="1.0"?>
<robot name="wheels" 
       xmlns:xacro="http://www.ros.org/wiki/xacro">

       <link
       name="wheel_back_left_link">
       <inertial>
         <origin
           xyz="2.6757E-09 2.4819E-09 -0.010577"
           rpy="0 0 0" />
         <mass
           value="2.5" />
         <inertia
           ixx="0.0033232"
           ixy="-1.1337E-08"
           ixz="8.1177E-11"
           iyy="0.0033232"
           iyz="-6.1399E-11"
           izz="0.0061353" />
       </inertial>
       <visual>
         <origin
           xyz="0 0 0"
           rpy="0 0 0" />
         <geometry>
           <mesh
             filename="package://deli_robo/meshes/wheel_back_left_link.STL" />
         </geometry>
         <material
           name="">
           <color
             rgba="0.75294 0.75294 0.75294 1" />
         </material>
       </visual>
       <collision>
         <origin
           xyz="0 0 0"
           rpy="0 0 0" />
         <geometry>
           <mesh
             filename="package://deli_robo/meshes/wheel_back_left_link.STL" />
         </geometry>
       </collision>
     </link>
     <joint
       name="joint_wheel_back_left"
       type="continuous">
       <origin
         xyz="-0.23154 0.2955 0.06"
         rpy="1.5708 0 3.1416" />
       <parent
         link="base_link" />
       <child
         link="wheel_back_left_link" />
       <axis
         xyz="0 0 1" />
         <dynamics damping="0.1" friction="0.5" />
     </joint>



     <link
       name="wheel_back_right_link">
       <inertial>
         <origin
           xyz="3.5038E-09 1.021E-09 0.010577"
           rpy="0 0 0" />
         <mass
           value="2.5" />
         <inertia
           ixx="0.0033232"
           ixy="-9.3654E-09"
           ixz="1.0986E-11"
           iyy="0.0033232"
           iyz="-1.0119E-10"
           izz="0.0061353" />
       </inertial>
       <visual>
         <origin
           xyz="0 0 0"
           rpy="0 0 0" />
         <geometry>
           <mesh
             filename="package://deli_robo/meshes/wheel_back_right_link.STL" />
         </geometry>
         <material
           name="">
           <color
             rgba="0.75294 0.75294 0.75294 1" />
         </material>
       </visual>
       <collision>
         <origin
           xyz="0 0 0"
           rpy="0 0 0" />
         <geometry>
           <mesh
             filename="package://deli_robo/meshes/wheel_back_right_link.STL" />
         </geometry>
       </collision>
     </link>
     <joint
       name="joint_wheel_back_right"
       type="continuous">
       <origin
         xyz="-0.23154 -0.2955 0.06"
         rpy="1.5708 0 3.1416" />
       <parent
         link="base_link" />
       <child
         link="wheel_back_right_link" />
       <axis
         xyz="0 0 1" />
         <dynamics damping="0.1" friction="0.5" />
     </joint>


     <link
       name="wheel_front_left_link">
       <inertial>
         <origin
           xyz="2.2922E-08 -3.5373E-10 0.00086907"
           rpy="0 0 0" />
         <mass
           value="2.5" />
         <inertia
           ixx="0.00054477"
           ixy="1.164E-11"
           ixz="5.0249E-11"
           iyy="0.00054477"
           iyz="2.8527E-12"
           izz="0.0010243" />
       </inertial>
       <visual>
         <origin
           xyz="0 0 0"
           rpy="0 0 0" />
         <geometry>
           <mesh
             filename="package://deli_robo/meshes/wheel_front_left_link.STL" />
         </geometry>
         <material
           name="">
           <color
             rgba="0.75294 0.75294 0.75294 1" />
         </material>
       </visual>
       <collision>
         <origin
           xyz="0 0 0"
           rpy="0 0 0" />
         <geometry>
           <mesh
             filename="package://deli_robo/meshes/wheel_front_left_link.STL" />
         </geometry>
       </collision>
     </link>
     <joint
       name="joint_wheel_front_left"
       type="continuous">
       <origin
         xyz="0.23 0.24887 0.033"
         rpy="1.5708 0 3.1416" />
       <parent
         link="base_link" />
       <child
         link="wheel_front_left_link" />
       <axis
         xyz="0 0 1" />
     </joint>

     <link
       name="wheel_front_right_link">
       <inertial>
         <origin
           xyz="2.2203E-08 -5.7057E-09 0.00086907"
           rpy="0 0 0" />
         <mass
           value="2.5" />
         <inertia
           ixx="0.00054477"
           ixy="2.5356E-11"
           ixz="4.9522E-11"
           iyy="0.00054477"
           iyz="-8.9807E-12"
           izz="0.0010243" />
       </inertial>
       <visual>
         <origin
           xyz="0 0 0"
           rpy="0 0 0" />
         <geometry>
           <mesh
             filename="package://deli_robo/meshes/wheel_front_right_link.STL" />
         </geometry>
         <material
           name="">
           <color
             rgba="0.75294 0.75294 0.75294 1" />
         </material>
       </visual>
       <collision>
         <origin
           xyz="0 0 0"
           rpy="0 0 0" />
         <geometry>
           <mesh
             filename="package://deli_robo/meshes/wheel_front_right_link.STL" />
         </geometry>
       </collision>
     </link>
     <joint
       name="joint_wheel_front_right"
       type="continuous">
       <origin
         xyz="0.23 -0.2595 0.033"
         rpy="1.5708 0 3.1416" />
       <parent
         link="base_link" />
       <child
         link="wheel_front_right_link" />
       <axis
         xyz="0 0 1" />
     </joint>

</robot>