<?xml version="1.0" encoding="utf-8"?>
<!-- =================================================================================== -->
<!-- |    This document was autogenerated by xacro from st.xacro                       | -->
<!-- |    EDITING THIS FILE BY HAND IS NOT RECOMMENDED                                 | -->
<!-- =================================================================================== -->
<robot name="st">
  <gazebo>
    <plugin filename="libgazebo_ros_diff_drive.so" name="differential_drive_controller">
      <legacyMode>false</legacyMode>
      <alwaysOn>true</alwaysOn>
      <updateRate>10</updateRate>
      <leftJoint>left_wheel_hinge</leftJoint>
      <rightJoint>right_wheel_hinge</rightJoint>
      <wheelSeparation>0.30</wheelSeparation>
      <wheelDiameter>0.2</wheelDiameter>
      <publishWheelTF>True</publishWheelTF>
      <torque>30</torque>
      <commandTopic>cmd_vel</commandTopic>
      <odometryTopic>odom</odometryTopic>
      <odometryFrame>odom</odometryFrame>
      <robotBaseFrame>base_link</robotBaseFrame>
    </plugin>
  </gazebo>
  <gazebo reference="base_link">
    <material>
        Gazebo/Gray
      </material>
  </gazebo>
  <gazebo reference="container_link">
    <material>
        Gazebo/Gray
      </material>
  </gazebo>
  <gazebo reference="lid_container_link">
    <material>
        Gazebo/Blue
      </material>
  </gazebo>
  <gazebo reference="left_wheel">
    <material>
        Gazebo/Black
      </material>
  </gazebo>
  <gazebo reference="right_wheel">
    <material>
        Gazebo/Black
      </material>
  </gazebo>
  <gazebo reference="wheel_front_right_link">
    <material>
        Gazebo/Black
      </material>
  </gazebo>
  <gazebo reference="wheel_front_left_link">
    <material>
        Gazebo/Black
      </material>
  </gazebo>
  <gazebo reference="hokuyo_link">
    <sensor name="head_hokuyo_sensor" type="ray">
      <pose>0 0 0 0 0 0</pose>
      <visualize>false</visualize>
      <update_rate>40</update_rate>
      <ray>
        <scan>
          <horizontal>
            <samples>100</samples>
            <resolution>2</resolution>
            <min_angle>-1.570796</min_angle>
            <max_angle>1.570796</max_angle>
          </horizontal>
        </scan>
        <range>
          <min>0.10</min>
          <max>30.0</max>
          <resolution>0.01</resolution>
        </range>
        <noise>
          <type>gaussian</type>
          <mean>0.0</mean>
          <stddev>0.001</stddev>
        </noise>
      </ray>
      <plugin filename="libgazebo_ros_laser.so" name="gazebo_ros_head_hokuyo_controller">
        <frameName>base_link</frameName>
        <topicName>st_scan</topicName>
      </plugin>
    </sensor>
  </gazebo>
  <gazebo>
    <plugin filename="libgazebo_ros_imu.so" name="imu_sensor">
      <alwaysOn>true</alwaysOn>
      <updateRate>50.0</updateRate>
      <bodyName>base_link</bodyName>
      <frameName>base_link</frameName>
      <topicName>imu</topicName>
      <serviceName>imu_service</serviceName>
      <gaussianNoise>0.01</gaussianNoise>
      <gyroscopeNoiseDensity>0.0001</gyroscopeNoiseDensity>
      <gyroscopeRandomWalk>0.0001</gyroscopeRandomWalk>
      <gyroscopeBiasCorrelationTime>1.0e3</gyroscopeBiasCorrelationTime>
      <accelerometerNoiseDensity>0.0001</accelerometerNoiseDensity>
      <accelerometerRandomWalk>0.0001</accelerometerRandomWalk>
      <accelerometerBiasCorrelationTime>1.0e3</accelerometerBiasCorrelationTime>
      <orientationNoise>0.001</orientationNoise>
      <linearAccelerationNoise>0.001</linearAccelerationNoise>
      <angularVelocityNoise>0.001</angularVelocityNoise>
    </plugin>
  </gazebo>
  <gazebo reference="gps_link">
    <material>Gazebo/Blue</material>
  </gazebo>
  <gazebo reference="depth">
    <material>Gazebo/Black</material>
  </gazebo>
  <gazebo reference="depth">
    <sensor name="depth_camera" type="depth">
      <update_rate>20</update_rate>
      <camera>
        <horizontal_fov>2.355</horizontal_fov>
        <image>
          <width>640</width>
          <height>480</height>
          <format>R8G8B8</format>
        </image>
        <clip>
          <near>0.001</near>
          <far>5</far>
        </clip>
      </camera>
      <plugin filename="libgazebo_ros_openni_kinect.so" name="camera_controller">
        <baseline>0.2</baseline>
        <alwaysOn>true</alwaysOn>
        <updateRate>10.0</updateRate>
        <cameraName/>
        <imageTopicName>color/image_raw</imageTopicName>
        <cameraInfoTopicName>color/camera_info</cameraInfoTopicName>
        <depthImageTopicName>depth/image_raw</depthImageTopicName>
        <depthImageInfoTopicName>depth/camera_info</depthImageInfoTopicName>
        <pointCloudTopicName>points2</pointCloudTopicName>
        <frameName>depth_link</frameName>
        <pointCloudCutoff>0.01</pointCloudCutoff>
        <pointCloudCutoffMax>5.0</pointCloudCutoffMax>
        <distortionK1>0.00000001</distortionK1>
        <distortionK2>0.00000001</distortionK2>
        <distortionK3>0.00000001</distortionK3>
        <distortionT1>0.00000001</distortionT1>
        <distortionT2>0.00000001</distortionT2>
        <CxPrime>0</CxPrime>
        <Cx>0</Cx>
        <Cy>0</Cy>
        <focalLength>0</focalLength>
        <hackBaseline>0.5</hackBaseline>
      </plugin>
    </sensor>
  </gazebo>
  <gazebo>
    <plugin filename="libhector_gazebo_ros_gps.so" name="gazebo_ros_gps">
      <updateRate>4.0</updateRate>
      <bodyName>gps_link</bodyName>
      <frameId>base_link</frameId>
      <topicName>gps</topicName>
      <velocityTopicName>gps/fix_velocity</velocityTopicName>
      <referenceLatitude>-30.06022459407145675</referenceLatitude>
      <referenceLongitude>-51.173913575780311191</referenceLongitude>
      <referenceHeading>90</referenceHeading>
      <referenceAltitude>10</referenceAltitude>
      <offset>0 0 0</offset>
      <drift>0.001 0.001 0.001</drift>
      <gaussianNoise>0.05 0.05 0.05</gaussianNoise>
      <velocityDrift>0.001 0.001 0.001</velocityDrift>
      <velocityGaussianNoise>0.5 0.5 0.5</velocityGaussianNoise>
    </plugin>
  </gazebo>
  <link name="base_link">
    <inertial>
      <origin rpy="0 0 0" xyz="-0.037666 0.19446 0.026"/>
      <mass value="3"/>
      <inertia ixx="0" ixy="0" ixz="0" iyy="0" iyz="0" izz="0"/>
    </inertial>
    <visual>
      <origin rpy="0 0 0" xyz="0 0 0"/>
      <geometry>
        <mesh filename="package://mybot/meshes/container_link.STL"/>
      </geometry>
      <material name="">
        <color rgba="0.75294 0.75294 0.75294 1"/>
      </material>
    </visual>
    <collision>
      <origin rpy="0 0 0" xyz="0 0 0"/>
      <geometry>
        <mesh filename="package://mybot/meshes/container_link.STL"/>
      </geometry>
    </collision>
  </link>
  <!--  Wheels -->
  <link name="left_wheel">
    <!--origin xyz="0.1 0.13 0.1" rpy="0 1.5707 1.5707"/-->
    <collision name="collision">
      <origin rpy="0 1.5707 1.5707" xyz="0 0 0"/>
      <geometry>
        <cylinder length="0.05" radius="0.1"/>
      </geometry>
    </collision>
    <visual name="left_wheel_visual">
      <origin rpy="0 1.5707 1.5707" xyz="0 0 0"/>
      <geometry>
        <cylinder length="0.05" radius="0.1"/>
      </geometry>
      <material name="black">
        <color rgba="0.0 0.0 0.0 1.0"/>
      </material>
    </visual>
    <inertial>
      <origin rpy="0 1.5707 1.5707" xyz="0 0 0"/>
      <mass value="5"/>
      <inertia ixx=".1" ixy="0.0" ixz="0.0" iyy=".1" iyz="0.0" izz=".1"/>
    </inertial>
  </link>
  <joint name="left_wheel_hinge" type="continuous">
    <origin rpy="0 0 0" xyz="-0.23 0.24887 0.033"/>
    <child link="left_wheel"/>
    <parent link="base_link"/>
    <axis rpy="0 0 0" xyz="0 1 0"/>
    <!-- <limit effort="10000" velocity="1000"/> -->
    <joint_properties damping="0.0" friction="0.0"/>
  </joint>
  <link name="right_wheel">
    <!--origin xyz="0.1 -0.13 0.1" rpy="0 1.5707 1.5707"/-->
    <collision name="collision">
      <origin rpy="0 1.5707 1.5707" xyz="0 0 0"/>
      <geometry>
        <cylinder length="0.05" radius="0.1"/>
      </geometry>
    </collision>
    <visual name="right_wheel_visual">
      <origin rpy="0 1.5707 1.5707" xyz="0 0 0"/>
      <geometry>
        <cylinder length="0.05" radius="0.1"/>
      </geometry>
      <material name="black">
        <color rgba="0.0 0.0 0.0 1.0"/>
      </material>
    </visual>
    <inertial>
      <origin rpy="0 1.5707 1.5707" xyz="0 0 0"/>
      <mass value="5"/>
      <inertia ixx=".1" ixy="0.0" ixz="0.0" iyy=".1" iyz="0.0" izz=".1"/>
    </inertial>
  </link>
  <joint name="right_wheel_hinge" type="continuous">
    <origin rpy="0 0 0" xyz="-0.23 -0.24887 0.033"/>
    <child link="right_wheel"/>
    <parent link="base_link"/>
    <axis rpy="0 0 0" xyz="0 1 0"/>
    <!-- <limit effort="10000" velocity="1000"/> -->
    <joint_properties damping="0.0" friction="0.0"/>
  </joint>
  <link name="wheel_front_left_link">
    <inertial>
      <origin rpy="0 0 0" xyz="2.2922E-08 -3.5373E-10 0.00086907"/>
      <mass value="0.6"/>
      <inertia ixx="0.00054477" ixy="1.164E-11" ixz="5.0249E-11" iyy="0.00054477" iyz="2.8527E-12" izz="0.0010243"/>
    </inertial>
    <visual>
      <origin rpy="0 0 0" xyz="0 0 0"/>
      <geometry>
        <cylinder length="0.05" radius="0.1"/>
      </geometry>
      <material name="black">
        <color rgba="0.0 0.0 0.0 1.0"/>
      </material>
    </visual>
    <collision>
      <origin rpy="0 0 0" xyz="0 0 0"/>
      <geometry>
        <cylinder length="0.05" radius="0.1"/>
      </geometry>
    </collision>
  </link>
  <joint name="joint_wheel_front_left" type="continuous">
    <origin rpy="1.5708 0 3.1416" xyz="0.23 0.25887 0.033"/>
    <parent link="base_link"/>
    <child link="wheel_front_left_link"/>
    <axis rpy="0 0 0" xyz="0 1 0"/>
  </joint>
  <link name="wheel_front_right_link">
    <inertial>
      <origin rpy="0 0 0" xyz="2.2203E-08 -5.7057E-09 0.00086907"/>
      <mass value="0.6"/>
      <inertia ixx="0.00054477" ixy="2.5356E-11" ixz="4.9522E-11" iyy="0.00054477" iyz="-8.9807E-12" izz="0.0010243"/>
    </inertial>
    <visual>
      <origin rpy="0 0 0" xyz="0 0 0"/>
      <geometry>
        <cylinder length="0.05" radius="0.1"/>
      </geometry>
      <material name="black">
        <color rgba="0.0 0.0 0.0 1.0"/>
      </material>
    </visual>
    <collision>
      <origin rpy="0 0 0" xyz="0 0 0"/>
      <geometry>
        <cylinder length="0.05" radius="0.1"/>
      </geometry>
    </collision>
  </link>
  <joint name="joint_wheel_front_right" type="continuous">
    <origin rpy="1.5708 0 3.1416" xyz="0.23 -0.25887 0.033"/>
    <parent link="base_link"/>
    <child link="wheel_front_right_link"/>
    <axis rpy="0 0 0" xyz="0 1 0"/>
  </joint>
  <!-- Hokuyo Laser -->
  <link name="hokuyo_link">
    <inertial>
      <origin rpy="0 0 0" xyz="-0.00064383 9.2927E-10 0.037832"/>
      <mass value="0.22916"/>
      <inertia ixx="0.00020894" ixy="1.295E-12" ixz="-1.1307E-06" iyy="0.00021335" iyz="-4.2308E-12" izz="0.00011244"/>
    </inertial>
    <visual>
      <origin rpy="0 0 0" xyz="0 0 0"/>
      <geometry>
        <mesh filename="package://mybot/meshes/lidar_point_link.STL"/>
      </geometry>
      <material name="">
        <color rgba="0 0 0 1"/>
      </material>
    </visual>
    <collision>
      <origin rpy="0 0 0" xyz="0 0 0"/>
      <geometry>
        <mesh filename="package://mybot/meshes/lidar_point_link.STL"/>
      </geometry>
    </collision>
  </link>
  <joint name="hokuyo_joint" type="fixed">
    <axis xyz="0 1 0"/>
    <origin rpy="0 0 0" xyz="0.245 -0.0051 0.23"/>
    <parent link="base_link"/>
    <child link="hokuyo_link"/>
  </joint>
  <!-- imu Link -->
  <link name="imu_sensor">
    <visual>
      <origin rpy="0 0 0" xyz="0.04 0 0.05"/>
      <geometry>
        <box size="0.07 0.07 0.03"/>
      </geometry>
      <material name="orange"/>
    </visual>
    <inertial>
      <origin rpy="0 0 0" xyz="0 0 1"/>
      <mass value="1"/>
      <inertia ixx="1.0" ixy="0.0" ixz="0.0" iyy="1.0" iyz="0.0" izz="1.0"/>
    </inertial>
  </link>
  <joint name="sensor_joint" type="fixed">
    <origin rpy="0 0 0" xyz="0.1 0 0.0574"/>
    <parent link="base_link"/>
    <child link="imu_sensor"/>
  </joint>
  <!-- gps Link -->
  <link name="gps_link">
    <inertial>
      <origin rpy="0 0 0" xyz="-0.002036 -0.001601 0.004"/>
      <mass value="0.0056708"/>
      <inertia ixx="2.7399E-07" ixy="8.0779E-24" ixz="-1.5978E-22" iyy="4.8412E-07" iyz="-8.3674E-24" izz="6.9802E-07"/>
    </inertial>
    <visual>
      <origin rpy="0 0 0" xyz="0 0 0"/>
      <geometry>
        <mesh filename="package://mybot/meshes/gps_ins_point_link.STL"/>
      </geometry>
      <material name="">
        <color rgba="1 0.50196 1 1"/>
      </material>
    </visual>
    <collision>
      <origin rpy="0 0 0" xyz="0 0 0"/>
      <geometry>
        <mesh filename="package://mybot/meshes/gps_ins_point_link.STL"/>
      </geometry>
    </collision>
  </link>
  <joint name="sensor_gps_joint" type="fixed">
    <origin rpy="0 0 0" xyz="0 0 0.0574"/>
    <parent link="base_link"/>
    <child link="gps_link"/>
    <axis xyz="0 0 0"/>
  </joint>
  <link name="container_link">
    <inertial>
      <origin rpy="0 0 0" xyz="0.010614 -0.0022011 0.091896"/>
      <mass value="10"/>
      <inertia ixx="0.18416" ixy="8.2071E-06" ixz="0.0032964" iyy="0.22207" iyz="2.5203E-06" izz="0.35275"/>
    </inertial>
    <visual>
      <origin rpy="0 0 0" xyz="0 0 0"/>
      <geometry>
        <mesh filename="package://mybot/meshes/container_link.STL"/>
      </geometry>
      <material name="">
        <color rgba="0.75294 0.75294 0.75294 1"/>
      </material>
    </visual>
    <collision>
      <origin rpy="0 0 0" xyz="0 0 0"/>
      <geometry>
        <mesh filename="package://mybot/meshes/container_link.STL"/>
      </geometry>
    </collision>
  </link>
  <joint name="link_container" type="fixed">
    <origin rpy="0 0 0" xyz="-0.07654 -0.0001 0.2"/>
    <parent link="base_link"/>
    <child link="container_link"/>
    <axis xyz="0 0 0"/>
  </joint>
  <link name="lid_container_link">
    <inertial>
      <origin rpy="0 0 0" xyz="0.29751 -0.040394 -1.3876E-07"/>
      <mass value="1"/>
      <inertia ixx="0.099856" ixy="0.022481" ixz="4.1838E-08" iyy="0.15535" iyz="2.9181E-08" izz="0.094701"/>
    </inertial>
    <visual>
      <origin rpy="0 0 0" xyz="0 0 0"/>
      <geometry>
        <mesh filename="package://mybot/meshes/lid_container_link.STL"/>
      </geometry>
      <material name="">
        <color rgba="0.1 0.25 1 0.8"/>
      </material>
    </visual>
    <collision>
      <origin rpy="0 0 0" xyz="0 0 0"/>
      <geometry>
        <mesh filename="package://mybot/meshes/lid_container_link.STL"/>
      </geometry>
    </collision>
  </link>
  <joint name="joint_lid" type="fixed">
    <origin rpy="1.5708 0 3.1416" xyz="0.16793 0 0.25293"/>
    <parent link="container_link"/>
    <child link="lid_container_link"/>
    <axis xyz="0 0 1"/>
  </joint>
  <!-- sonar Link -->
  <!-- <link
    name="sonar_link">
    <inertial>
      <origin
        xyz="-0.0051004 -6.5642E-16 0.020902"
        rpy="0 0 0" />
      <mass
        value="0.17044" />
      <inertia
        ixx="0.0019045"
        ixy="-4.3877E-18"
        ixz="2.391E-05"
        iyy="0.00012619"
        iyz="2.9518E-19"
        izz="0.0018177" />
    </inertial>
    <visual>
      <origin
        xyz="0 0 0"
        rpy="0 0 0" />
      <geometry>
        <mesh
          filename="package://mybot/meshes/sonar_link.STL" />
      </geometry>
      <material
        name="">
        <color
          rgba="0.5294 0.5294 0.5294 1" />
      </material>
    </visual>
    <collision>
      <origin
        xyz="0 0 0"
        rpy="0 0 0" />
      <geometry>
        <mesh
          filename="package://mybot/meshes/sonar_link.STL" />
      </geometry>
    </collision>
</link>
<joint
    name="joint_sonar"
    type="fixed">
    <origin
      xyz="0.218 0 0.2"
      rpy="0 0 0" />
    <parent
      link="base_link" />
    <child
      link="sonar_link" />
    <axis
      xyz="0 0 0" />
</joint> -->
  <!-- camera xyz="-0.00033186 3.8806E-17 0.023695"-->
  <link name="depth">
    <visual>
      <origin rpy="0 0 0" xyz="0 0 0"/>
      <geometry>
        <mesh filename="package://mybot/meshes/stereo_link.STL"/>
      </geometry>
    </visual>
    <collision name="collision_depth">
      <geometry>
        <mesh filename="package://mybot/meshes/stereo_link.STL"/>
      </geometry>
    </collision>
    <inertial>
      <mass value="0.2"/>
      <origin rpy="0 0 0" xyz="0 0 0"/>
      <inertia ixx="0.1" ixy="0" ixz="0" iyy=".1" iyz="0" izz=".1"/>
    </inertial>
  </link>
  <joint name="joint_depth_chassis" type="fixed">
    <origin rpy="0 0 0" xyz="0.245 -0.0051 0.3"/>
    <child link="depth"/>
    <parent link="base_link"/>
  </joint>
  <link name="depth_link"/>
  <joint name="joint_depth_link" type="fixed">
    <origin rpy="-1.5707 0 -1.5707" xyz="0.245 -0.0051 0.3"/>
    <child link="depth_link"/>
    <parent link="base_link"/>
  </joint>
  <material name="orange">
    <color rgba="1.0 0.423529411765 0.0392156862745 1.0"/>
  </material>
</robot>
